E       AssertionError: 10000 != 5001

tests/mega/account/test_personal_account.py:174: AssertionError
------------------------------------ Captured stderr call -------------------------------------
{"asctime": "2021-11-26 17:09:00,722", "levelname": "INFO", "funcName": "_call_api", "message": "start request", "method": "post", "parameters": {"timeout": 90, "headers": {"Authorization": "680cd5c0-30c6-013a-5b61-4e8bc6baf9db"}, "json": {"subs": {}, "web_source": "reach", "dist_version": "v1.0", "mobile": "17730353740", "name": "正式账号_33", "email": "zhongjian@jwac.net jianweicom@263.net", "sub_firm_id": 169783, "sub_contact_id": 1225884, "sub_start": 1637917740, "sub_end": 1640509740, "login_start": 1637917740, "login_end": 1640509740, "package_type": 3}}, "url": "http://crm-in-api.dev1.rccchina.com/app_users", "request_id": 351, "attachment": null}
{"asctime": "2021-11-26 17:09:00,786", "levelname": "INFO", "funcName": "_call_api", "message": "got response", "response": "{\"code\":5001,\"data\":{\"code\":-999,\"message\":\"server allot response err: 14:Connection reset by peer. debug_error_string:{\\\"created\\\":\\\"@1637917740.776002083\\\",\\\"description\\\":\\\"Error received from peer ipv4:10.85.189.101:50051\\\",\\\"file\\\":\\\"src/core/lib/surface/call.cc\\\",\\\"file_line\\\":1062,\\\"grpc_message\\\":\\\"Connection reset by peer\\\",\\\"grpc_status\\\":14}\",\"data\":null},\"message\":\"server allot response err: 14:Connection reset by peer. debug_error_string:{\\\"created\\\":\\\"@1637917740.776002083\\\",\\\"description\\\":\\\"Error received from peer ipv4:10.85.189.101:50051\\\",\\\"file\\\":\\\"src/core/lib/surface/call.cc\\\",\\\"file_line\\\":1062,\\\"grpc_message\\\":\\\"Connection reset by peer\\\",\\\"grpc_status\\\":14}\",\"created_at\":1637917740,\"request_id\":\"a566d750-c4c3-92a5-8b84-9cb8740b104b\"}", "request_id": 351, "is_json_format": true, "url": "http://crm-in-api.dev1.rccchina.com/app_users", "status_code": 200, "latency": 63, "attachment": null}
-------------------------------------- Captured log call --------------------------------------
INFO     qav5.http.client:client.py:105 start request
INFO     qav5.http.client:client.py:126 got response
=================================== short test summary info ===================================
FAILED tests/mega/account/test_account.py::TestSubscribersDetails::test_get_account_bid_view
FAILED tests/mega/account/test_personal_account.py::TestAppUsersSetting::test_app_users_setting_allot_admin
FAILED tests/mega/account/test_personal_account.py::TestAppUsersSetting::test_app_users_setting_allot_admin2
FAILED tests/mega/account/test_personal_account.py::TestAppUsersSetting::test_app_users_setting_crm
FAILED tests/mega/account/test_personal_account.py::TestAppUsersSetting::test_app_users_setting_pl_style
FAILED tests/mega/account/test_personal_account.py::TestAppUsersSetting::test_app_users_setting_pl_style2
FAILED tests/mega/account/test_personal_account.py::TestAppUsersShow::test_app_users_show_base
FAILED tests/mega/account/test_personal_account.py::TestAppUsersShow::test_app_users_show_free
FAILED tests/mega/account/test_personal_account.py::TestAppUsersSubCreate::test_app_users_sub_create
FAILED tests/mega/account/test_personal_account.py::TestAppUsersSubCreate::test_app_users_sub_create_base_out
FAILED tests/mega/account/test_personal_account.py::TestAppUsersSubCreate::test_app_users_sub_create_base_to_free
FAILED tests/mega/account/test_personal_account.py::TestAppUsersSubCreate::test_app_users_sub_create_free_to_base
FAILED tests/mega/account/test_personal_account.py::TestAppUsersSubCreate::test_app_users_sub_create_mobile_error
FAILED tests/mega/account/test_personal_account.py::TestAppUsersSubCreate::test_app_users_sub_create_mobile_none
FAILED tests/mega/account/test_personal_account.py::TestUserBatchCreate::test_scenario_all
FAILED tests/mega/account/test_personal_account.py::TestUserCreate::test_app_users_create_valid_fee
==================== 16 failed, 71 passed, 2 skipped in 115.27s (0:01:55) =====================
